Workbook

Sheet README
A1: Название проекта:
A2: Анализ продаж супермаркета за 2019 год
A4: Источник данных:
A5: Датасет с GitHub (Supermarket Sales)
A7: Инструменты:
A8: Microsoft Excel
A10: Что сделано:
A11: • Очистка и подготовка данных
A12: • Создание вычисляемых столбцов для переформатирования дат в числа (формулы ЗНАЧЕН, ЕСЛИ, ЕОШ, НАЙТИ и др.)
A13: • 5 сводных таблиц по ключевым срезам: гендер, товары, регионы, филиалы, время
A14: • Визуализация в виде дашборда
A15: • Бизнес-выводы и рекомендации по каждому срезу
... A28: 4. Пик продаж: январь-февраль, часы 13-14 и 18-19

Sheet Raw Data
A1: Invoice ID | B1: Branch | C1: City | D1: Customer type | E1: Gender | F1: Product line | G1: Unit price | H1: Quantity | I1: Tax 5% | J1: Total | K1: Date | L1: Time | M1: Payment | N1: Cogs | O1: Gross margin percentage | P1: Gross income | Q1: Rating | T1: Branch | U1: City | V1: Customer type | W1: Gender | X1: Product line
A2: 750-67-8428 | B2: A | C2: Yangon | D2: Member | E2: Female | F2: Health and beauty | G2: 74.69 | H2: 7 | I2: 26.1415 | J2: 548.9715 | K2: 43586 | L2: 0.54722222 | M2: Ewallet | N2: 522.83 | O2: 4.7619048 | P2: 26.1415 | Q2: 46031 | T2: A | U2: Yangon | V2: Member | W2: Female | X2: Health and beauty
A3: 226-31-3081 | B3: C | C3: Naypyitaw | D3: Normal | E3: Female | F3: Electronic accessories | G3: 15.28 | H3: 5 | I3: 30011 | J3: 80.22 | K3: 43680 | L3: 0.43680556 | M3: Cash | N3: 76.4 | O3: 4.7619048 | P3: 30011 | Q3: 46182 | T3: C | U3: Naypyitaw | V3: Normal | W3: Male | X3: Electronic accessories
A4: 631-41-3108 | B4: A | C4: Yangon | D4: Normal | E4: Male | F4: Home and lifestyle | G4: 46.33 | H4: 7 | I4: 16.2155 | J4: 340.5255 | K4: 43527 | L4: 0.55763889 | M4: Credit card | N4: 324.31 | O4: 4.7619048 | P4: 16.2155 | Q4: 46119 | T4: B | U4: Mandalay | X4: Home and lifestyle
A5: 123-19-1176 | B5: A | C5: Yangon | D5: Member | E5: Male | F5: Health and beauty | G5: 58.22 | H5: 8 | I5: 23.288 | J5: 489.048 | K5: 1/27/2019 | L5: 0.85625 | M5: Ewallet | N5: 465.76 | O5: 4.7619048 | P5: 23.288 | Q5: 46120 | X5: Sports and travel
A6: 373-73-7910 | B6: A | C6: Yangon | D6: Normal | E6: Male | F6: Sports and travel | G6: 86.31 | H6: 7 | I6: 30.2085 | J6: 634.3785 | K6: 43679 | L6: 0.44236111 | M6: Ewallet | N6: 604.17 | O6: 4.7619048 | P6: 30.2085 | Q6: 46086 | X6: Food and beverages
A7: 699-14-3026 | B7: C | C7: Naypyitaw | D7: Normal | E7: Male | F7: Electronic accessories | G7: 85.39 | H7: 7 | I7: 29.8865 | J7: 627.6165 | K7: 3/25/2019 | L7: 0.77083333 | M7: Ewallet | N7: 597.73 | O7: 4.7619048 | P7: 29.8865 | Q7: 46026 | X7: Fashion accessories
A8: 355-53-5943 | B8: A | C8: Yangon | D8: Member | E8: Female | F8: Electronic accessories | G8: 68.84 | H8: 6 | I8: 20.652 | J8: 433.692 | K8: 2/25/2019 | L8: 0.60833333 | M8: Ewallet | N8: 413.04 | O8: 4.7619048 | P8: 20.652 | Q8: 46239
A9: 315-22-5665 | B9: C | C9: Naypyitaw | D9: Normal | E9: Female | F9: Home and lifestyle | G9: 73.56 | H9: 10 | I9: 36.78 | J9: 772.38 | K9: 2/24/2019 | L9: 0.48472222 | M9: Ewallet | N9: 735.6 | O9: 4.7619048 | P9: 36.78 | Q9: 8
A10: 665-32-9167 | B10: A | C10: Yangon | D10: Member | E10: Female | F10: Health and beauty | G10: 36.26 | H10: 2 | I10: 3.626 | J10: 76.146 | K10: 43739 | L10: 0.71875 | M10: Credit card | N10: 72.52 | O10: 4.7619048 | P10: 3.626 | Q10: 46060
A11: 692-92-5582 | B11: B | C11: Mandalay | D11: Member | E11: Female | F11: Food and beverages | G11: 54.84 | H11: 3 | I11: 8.226 | J11: 172.746 | K11: 2/20/2019 | L11: 0.56041667 | M11: Credit card | N11: 164.52 | O11: 4.7619048 | P11: 8.226 | Q11: 46270
A12: 351-62-0822 | B12: B | C12: Mandalay | D12: Member | E12: Female | F12: Fashion accessories | G12: 14.48 | H12: 4 | I12: 2.896 | J12: 60.816 | K12: 43618 | L12: 0.75486111 | M12: Ewallet | N12: 57.92 | O12: 4.7619048 | P12: 2.896 | Q12: 46146
A13: 529-56-3974 | B13: B | C13: Mandalay | D13: Member | E13: Male | F13: Electronic accessories | G13: 25.51 | H13: 4 | I13: 5.102 | J13: 107.142 | K13: 43711 | L13: 0.71041667 | M13: Cash | N13: 102.04 | O13: 4.7619048 | P13: 5.102 | Q13: 46240
A14: 365-64-0515 | B14: A | C14: Yangon | D14: Normal | E14: Female | F14: Electronic accessories | G14: 46.95 | H14: 5 | I14: 27699 | J14: 246.4875 | K14: 43801 | L14: 0.43402778 | M14: Ewallet | N14: 234.75 | O14: 4.7619048 | P14: 27699 | Q14: 46029
A15: 252-56-2699 | B15: A | C15: Yangon | D15: Normal | E15: Male | F15: Food and beverages | G15: 43.19 | H15: 10 | I15: 21.595 | J15: 453.495 | K15: 43648 | L15: 0.7 | M15: Ewallet | N15: 431.9 | O15: 4.7619048 | P15: 21.595 | Q15: 46061
A16: 829-34-3910 | B16: A | C16: Yangon | D16: Normal | E16: Female | F16: Health and beauty | G16: 71.38 | H16: 10 | I16: 35.69 | J16: 749.49 | K16: 3/29/2019 | L16: 0.80625 | M16: Cash | N16: 713.8 | O16: 4.7619048 | P16: 35.69 | Q16: 46208
A17: 299-46-1805 | B17: B | C17: Mandalay | D17: Member | E17: Female | F17: Sports and travel | G17: 93.72 | H17: 6 | I17: 28.116 | J17: 590.436 | K17: 1/15/2019 | L17: 0.67986111 | M17: Cash | N17: 562.32 | O17: 4.7619048 | P17: 28.116 | Q17: 46146
A18: 656-95-9349 | B18: A | C18: Yangon | D18: Member | E18: Female | F18: Health and beauty | G18: 68.93 | H18: 7 | I18: 24.1255 | J18: 506.6355 | K18: 43772 | L18: 0.46041667 | M18: Credit card | N18: 482.51 | O18: 4.7619048 | P18: 24.1255 | Q18: 46177
A19: 765-26-6951 | B19: A | C19: Yangon | D19: Normal | E19: Male | F19: Sports and travel | G19: 72.61 | H19: 6 | I19: 21.783 | J19: 457.443 | K19: 43466 | L19: 0.44375 | M19: Credit card | N19: 435.66 | O19: 4.7619048 | P19: 21.783 | Q19: 46271
A20: 329-62-1586 | B20: A | C20: Yangon | D20: Normal | E20: Male | F20: Food and beverages | G20: 54.67 | H20: 3 | I20: 38565 | J20: 172.2105 | K20: 1/21/2019 | L20: 0.75 | M20: Credit card | N20: 164.01 | O20: 4.7619048 | P20: 38565 | Q20: 46181
A21: 319-50-3348 | B21: B | C21: Mandalay | D21: Normal | E21: Female | F21: Home and lifestyle | G21: 40.3 | H21: 2 | I21: 46085 | J21: 84.63 | K21: 43772 | L21: 0.64583333 | M21: Ewallet | N21: 80.6 | O21: 4.7619048 | P21: 46085 | Q21: 46116
A22: 300-71-4605 | B22: C | C22: Naypyitaw | D22: Member | E22: Male | F22: Electronic accessories | G22: 86.04 | H22: 5 | I22: 21.51 | J22: 451.71 | K22: 2/25/2019 | L22: 0.475 | M22: Ewallet | N22: 430.2 | O22: 4.7619048 | P22: 21.51 | Q22: 46238
A23: 371-85-5789 | B23: B | C23: Mandalay | D23: Normal | E23: Male | F23: Health and beauty | G23: 87.98 | H23: 3 | I23: 13.197 | J23: 277.137 | K23: 43588 | L23: 0.44444444 | M23: Ewallet | N23: 263.94 | O23: 4.7619048 | P23: 13.197 | Q23: 46027
A24: 273-16-6619 | B24: B | C24: Mandalay | D24: Normal | E24: Male | F24: Home and lifestyle | G24: 33.2 | H24: 2 | I24: 11749 | J24: 69.72 | K24: 3/15/2019 | L24: 0.51388889 | M24: Credit card | N24: 66.4 | O24: 4.7619048 | P24: 11749 | Q24: 46116
A25: 636-48-8204 | B25: A | C25: Yangon | D25: Normal | E25: Male | F25: Electronic accessories | G25: 34.56 | H25: 5 | I25: 23590 | J25: 181.44 | K25: 2/17/2019 | L25: 0.46875 | M25: Ewallet | N25: 172.8 | O25: 4.7619048 | P25: 23590 | Q25: 46274
A26: 549-59-1358 | B26: A | C26: Yangon | D26: Member | E26: Male | F26: Sports and travel | G26: 88.63 | H26: 3 | I26: 13.2945 | J26: 279.1845 | K26: 43499 | L26: 0.73333333 | M26: Ewallet | N26: 265.89 | O26: 4.7619048 | P26: 13.2945 | Q26: 6
A27: 227-03-5010 | B27: A | C27: Yangon | D27: Member | E27: Female | F27: Home and lifestyle | G27: 52.59 | H27: 8 | I27: 21.036 | J27: 441.756 | K27: 3/22/2019 | L27: 0.80555556 | M27: Credit card | N27: 420.72 | O27: 4.7619048 | P27: 21.036 | Q27: 46150
A28: 649-29-6775 | B28: B | C28: Mandalay | D28: Normal | E28: Male | F28: Fashion accessories | G28: 33.52 | H28: 1 | I28: 1.676 | J28: 35.196 | K28: 43679 | L28: 0.64652778 | M28: Cash | N28: 33.52 | O28: 4.7619048 | P28: 1.676 | Q28: 46209
A29: 189-17-4241 | B29: A | C29: Yangon | D29: Normal | E29: Female | F29: Fashion accessories | G29: 87.67 | H29: 2 | I29: 8.767 | J29: 184.107 | K29: 43741 | L29: 0.51180556 | M29: Credit card | N29: 175.34 | O29: 4.7619048 | P29: 8.767 | Q29: 46210
A30: 145-94-9061 | B30: B | C30: Mandalay | D30: Normal | E30: Female | F30: Food and beverages | G30: 88.36 | H30: 5 | I30: 46287 | J30: 463.89 | K30: 1/25/2019 | L30: 0.825 | M30: Cash | N30: 441.8 | O30: 4.7619048 | P30: 46287 | Q30: 46182
A31: 848-62-7243 | B31: A | C31: Yangon | D31: Normal | E31: Male | F31: Health and beauty | G31: 24.89 | H31: 9 | I31: 38657 | J31: 235.2105 | K31: 3/15/2019 | L31: 0.65 | M31: Cash | N31: 224.01 | O31: 4.7619048 | P31: 38657 | Q31: 46119
A32: 871-79-8483 | B32: B | C32: Mandalay | D32: Normal | E32: Male | F32: Fashion accessories | G32: 94.13 | H32: 5 | I32: 23.5325 | J32: 494.1825 | K32: 2/25/2019 | L32: 0.81875 | M32: Credit card | N32: 470.65 | O32: 4.7619048 | P32: 23.5325 | Q32: 46238
A33: 149-71-6266 | B33: B | C33: Mandalay | D33: Member | E33: Male | F33: Sports and travel | G33: 78.07 | H33: 9 | I33: 35.1315 | J33: 737.7615 | K33: 1/28/2019 | L33: 0.52986111 | M33: Cash | N33: 702.63 | O33: 4.7619048 | P33: 35.1315 | Q33: 46146
A34: 640-49-2076 | B34: B | C34: Mandalay | D34: Normal | E34: Male | F34: Sports and travel | G34: 83.78 | H34: 8 | I34: 33.512 | J34: 703.752 | K34: 43739 | L34: 0.61736111 | M34: Cash | N34: 670.24 | O34: 4.7619048 | P34: 33.512 | Q34: 46027
A35: 595-11-5460 | B35: A | C35: Yangon | D35: Normal | E35: Male | F35: Health and beauty | G35: 96.58 | H35: 2 | I35: 9.658 | J35: 202.818 | K35: 3/15/2019 | L35: 0.425 | M35: Credit card | N35: 193.16 | O35: 4.7619048 | P35: 9.658 | Q35: 46027
A36: 183-56-6882 | B36: C | C36: Naypyitaw | D36: Member | E36: Female | F36: Food and beverages | G36: 99.42 | H36: 4 | I36: 19.884 | J36: 417.564 | K36: 43618 | L36: 0.44583333 | M36: Ewallet | N36: 397.68 | O36: 4.7619048 | P36: 19.884 | Q36: 46149
A37: 232-16-2483 | B37: C | C37: Naypyitaw | D37: Member | E37: Female | F37: Sports and travel | G37: 68.12 | H37: 1 | I37: 3.406 | J37: 71.526 | K37: 43647 | L37: 0.51944444 | M37: Ewallet | N37: 68.12 | O37: 4.7619048 | P37: 3.406 | Q37: 46240
A38: 129-29-8530 | B38: A | C38: Yangon | D38: Member | E38: Male | F38: Sports and travel | G38: 62.62 | H38: 5 | I38: 15.655 | J38: 328.755 | K38: 43741 | L38: 0.80208333 | M38: Ewallet | N38: 313.1 | O38: 4.7619048 | P38: 15.655 | Q38: 7
A39: 272-65-1806 | B39: A | C39: Yangon | D39: Normal | E39: Female | F39: Electronic accessories | G39: 60.88 | H39: 9 | I39: 27.396 | J39: 575.316 | K39: 1/15/2019 | L39: 0.72013889 | M39: Ewallet | N39: 547.92 | O39: 4.7619048 | P39: 27.396 | Q39: 46207
A40: 333-73-7901 | B40: C | C40: Naypyitaw | D40: Normal | E40: Female | F40: Health and beauty | G40: 54.92 | H40: 8 | I40: 21.968 | J40: 461.328 | K40: 3/23/2019 | L40: 0.55833333 | M40: Ewallet | N40: 439.36 | O40: 4.7619048 | P40: 21.968 | Q40: 46180
...

Sheet Cleaned Data
A1: Invoice ID | B1: Branch | C1: City | D1: Customer type | E1: Gender | F1: Product line | G1: Unit price | H1: Quantity | I1: Tax 5% | J1: Total | K1: Date | L1: Time | M1: Payment | N1: Cogs | O1: Gross margin percentage | P1: Gross income | Q1: Rating
A2: 750-67-8428 | B2: A | C2: Yangon | D2: Member | E2: Female | F2: Health and beauty | G2: =VALUE(IF(AND(ISERR(FIND(".",'Raw Data'!G2)),LEN('Raw Data'!G2)=5), IF(YEAR('Raw Data'!G2)=2026,CONCATENATE(DAY('Raw Data'!G2),".",IF(LEN(MONTH('Raw Data'!G2))=2,MONTH('Raw Data'!G2),CONCATENATE("0",MONTH('Raw Data'!G2)))),CONCATENATE(MONTH('Raw Data'!G2),".",RIGHT(YEAR('Raw Data'!G2),2))),'Raw Data'!G2)) -> 74.69 | H2: ='Raw Data'!H2 -> 7 | I2: =J2-G2*H2 -> 26.1415 | J2: ='Raw Data'!J2 -> 548.9715 | K2: =VALUE(IFERROR(VALUE('Raw Data'!K2),CONCATENATE(MID('Raw Data'!K2,3,2),".","0",LEFT('Raw Data'!K2,1),".", RIGHT('Raw Data'!K2,4)))) -> 43586 | L2: ='Raw Data'!L2 -> 0.54722222 | M2: Ewallet | N2: =VALUE(IF(AND(ISERR(FIND(".",'Raw Data'!N2)),LEN('Raw Data'!N2)=5), IF(YEAR('Raw Data'!N2)=2026,CONCATENATE(DAY('Raw Data'!N2),".",IF(LEN(MONTH('Raw Data'!N2))=2,MONTH('Raw Data'!N2),CONCATENATE("0",MONTH('Raw Data'!N2)))),CONCATENATE(MONTH('Raw Data'!N2),".",RIGHT(YEAR('Raw Data'!N2),2))),'Raw Data'!N2)) -> 522.83 | O2: =P2/J2*100 -> 4.7619048 | P2: =J2-N2 -> 26.1415 | Q2: =VALUE(IF(AND(ISERR(FIND(".",'Raw Data'!Q2)),LEN('Raw Data'!Q2)=5), IF(YEAR('Raw Data'!Q2)=2026,CONCATENATE(DAY('Raw Data'!Q2),".",IF(LEN(MONTH('Raw Data'!Q2))=2,MONTH('Raw Data'!Q2),CONCATENATE(MONTH('Raw Data'!Q2)))),CONCATENATE(MONTH('Raw Data'!Q2),".",RIGHT(YEAR('Raw Data'!Q2),2))),'Raw Data'!Q2)) -> 9.1
A3: 226-31-3081 | B3: C | C3: Naypyitaw | D3: Normal | E3: Female | F3: Electronic accessories | G3: =VALUE(IF(AND(ISERR(FIND(".",'Raw Data'!G3)),LEN('Raw Data'!G3)=5), IF(YEAR('Raw Data'!G3)=2026,CONCATENATE(DAY('Raw Data'!G3),".",IF(LEN(MONTH('Raw Data'!G3))=2,MONTH('Raw Data'!G3),CONCATENATE("0",MONTH('Raw Data'!G3)))),CONCATENATE(MONTH('Raw Data'!G3),".",RIGHT(YEAR('Raw Data'!G3),2))),'Raw Data'!G3)) -> 15.28 | H3: ='Raw Data'!H3 -> 5 | I3: =J3-G3*H3 -> 3.82 | J3: ='Raw Data'!J3 -> 80.22 | K3: =VALUE(IFERROR(VALUE('Raw Data'!K3),CONCATENATE(MID('Raw Data'!K3,3,2),".","0",LEFT('Raw Data'!K3,1),".", RIGHT('Raw Data'!K3,4)))) -> 43680 | L3: ='Raw Data'!L3 -> 0.43680556 | M3: Cash | N3: =VALUE(IF(AND(ISERR(FIND(".",'Raw Data'!N3)),LEN('Raw Data'!N3)=5), IF(YEAR('Raw Data'!N3)=2026,CONCATENATE(DAY('Raw Data'!N3),".",IF(LEN(MONTH('Raw Data'!N3))=2,MONTH('Raw Data'!N3),CONCATENATE("0",MONTH('Raw Data'!N3)))),CONCATENATE(MONTH('Raw Data'!N3),".",RIGHT(YEAR('Raw Data'!N3),2))),'Raw Data'!N3)) -> 76.4 | O3: =P3/J3*100 -> 4.7619048 | P3: =J3-N3 -> 3.82 | Q3: =VALUE(IF(AND(ISERR(FIND(".",'Raw Data'!Q3)),LEN('Raw Data'!Q3)=5), IF(YEAR('Raw Data'!Q3)=2026,CONCATENATE(DAY('Raw Data'!Q3),".",IF(LEN(MONTH('Raw Data'!Q3))=2,MONTH('Raw Data'!Q3),CONCATENATE(MONTH('Raw Data'!Q3)))),CONCATENATE(MONTH('Raw Data'!Q3),".",RIGHT(YEAR('Raw Data'!Q3),2))),'Raw Data'!Q3)) -> 9.6
A4: 631-41-3108 | B4: A | C4: Yangon | D4: Normal | E4: Male | F4: Home and lifestyle | G4: =VALUE(IF(AND(ISERR(FIND(".",'Raw Data'!G4)),LEN('Raw Data'!G4)=5), IF(YEAR('Raw Data'!G4)=2026,CONCATENATE(DAY('Raw Data'!G4),".",IF(LEN(MONTH('Raw Data'!G4))=2,MONTH('Raw Data'!G4),CONCATENATE("0",MONTH('Raw Data'!G4)))),CONCATENATE(MONTH('Raw Data'!G4),".",RIGHT(YEAR('Raw Data'!G4),2))),'Raw Data'!G4)) -> 46.33 | H4: ='Raw Data'!H4 -> 7 | I4: =J4-G4*H4 -> 16.2155 | J4: ='Raw Data'!J4 -> 340.5255 | K4: =VALUE(IFERROR(VALUE('Raw Data'!K4),CONCATENATE(MID('Raw Data'!K4,3,2),".","0",LEFT('Raw Data'!K4,1),".", RIGHT('Raw Data'!K4,4)))) -> 43527 | L4: ='Raw Data'!L4 -> 0.55763889 | M4: Credit card | N4: =VALUE(IF(AND(ISERR(FIND(".",'Raw Data'!N4)),LEN('Raw Data'!N4)=5), IF(YEAR('Raw Data'!N4)=2026,CONCATENATE(DAY('Raw Data'!N4),".",IF(LEN(MONTH('Raw Data'!N4))=2,MONTH('Raw Data'!N4),CONCATENATE("0",MONTH('Raw Data'!N4)))),CONCATENATE(MONTH('Raw Data'!N4),".",RIGHT(YEAR('Raw Data'!N4),2))),'Raw Data'!N4)) -> 324.31 | O4: =P4/J4*100 -> 4.7619048 | P4: =J4-N4 -> 16.2155 | Q4: =VALUE(IF(AND(ISERR(FIND(".",'Raw Data'!Q4)),LEN('Raw Data'!Q4)=5), IF(YEAR('Raw Data'!Q4)=2026,CONCATENATE(DAY('Raw Data'!Q4),".",IF(LEN(MONTH('Raw Data'!Q4))=2,MONTH('Raw Data'!Q4),CONCATENATE(MONTH('Raw Data'!Q4)))),CONCATENATE(MONTH('Raw Data'!Q4),".",RIGHT(YEAR('Raw Data'!Q4),2))),'Raw Data'!Q4)) -> 7.4
A5: 123-19-1176 | B5: A | C5: Yangon | D5: Member | E5: Male | F5: Health and beauty | G5: =VALUE(IF(AND(ISERR(FIND(".",'Raw Data'!G5)),LEN('Raw Data'!G5)=5), IF(YEAR('Raw Data'!G5)=2026,CONCATENATE(DAY('Raw Data'!G5),".",IF(LEN(MONTH('Raw Data'!G5))=2,MONTH('Raw Data'!G5),CONCATENATE("0",MONTH('Raw Data'!G5)))),CONCATENATE(MONTH('Raw Data'!G5),".",RIGHT(YEAR('Raw Data'!G5),2))),'Raw Data'!G5)) -> 58.22 | H5: ='Raw Data'!H5 -> 8 | I5: =J5-G5*H5 -> 23.288 | J5: ='Raw Data'!J5 -> 489.048 | K5: =VALUE(IFERROR(VALUE('Raw Data'!K5),CONCATENATE(MID('Raw Data'!K5,3,2),".","0",LEFT('Raw Data'!K5,1),".", RIGHT('Raw Data'!K5,4)))) -> 43492 | L5: ='Raw Data'!L5 -> 0.85625 | M5: Ewallet | N5: =VALUE(IF(AND(ISERR(FIND(".",'Raw Data'!N5)),LEN('Raw Data'!N5)=5), IF(YEAR('Raw Data'!N5)=2026,CONCATENATE(DAY('Raw Data'!N5),".",IF(LEN(MONTH('Raw Data'!N5))=2,MONTH('Raw Data'!N5),CONCATENATE("0",MONTH('Raw Data'!N5)))),CONCATENATE(MONTH('Raw Data'!N5),".",RIGHT(YEAR('Raw Data'!N5),2))),'Raw Data'!N5)) -> 465.76 | O5: =P5/J5*100 -> 4.7619048 | P5: =J5-N5 -> 23.288 | Q5: =VALUE(IF(AND(ISERR(FIND(".",'Raw Data'!Q5)),LEN('Raw Data'!Q5)=5), IF(YEAR('Raw Data'!Q5)=2026,CONCATENATE(DAY('Raw Data'!Q5),".",IF(LEN(MONTH('Raw Data'!Q5))=2,MONTH('Raw Data'!Q5),CONCATENATE(MONTH('Raw Data'!Q5)))),CONCATENATE(MONTH('Raw Data'!Q5),".",RIGHT(YEAR('Raw Data'!Q5),2))),'Raw Data'!Q5)) -> 8.4
A6: 373-73-7910 | B6: A | C6: Yangon | D6: Normal | E6: Male | F6: Sports and travel | G6: =VALUE(IF(AND(ISERR(FIND(".",'Raw Data'!G6)),LEN('Raw Data'!G6)=5), IF(YEAR('Raw Data'!G6)=2026,CONCATENATE(DAY('Raw Data'!G6),".",IF(LEN(MONTH('Raw Data'!G6))=2,MONTH('Raw Data'!G6),CONCATENATE("0",MONTH('Raw Data'!G6)))),CONCATENATE(MONTH('Raw Data'!G6),".",RIGHT(YEAR('Raw Data'!G6),2))),'Raw Data'!G6)) -> 86.31 | H6: ='Raw Data'!H6 -> 7 | I6: =J6-G6*H6 -> 30.2085 | J6: ='Raw Data'!J6 -> 634.3785 | K6: =VALUE(IFERROR(VALUE('Raw Data'!K6),CONCATENATE(MID('Raw Data'!K6,3,2),".","0",LEFT('Raw Data'!K6,1),".", RIGHT('Raw Data'!K6,4)))) -> 43679 | L6: ='Raw Data'!L6 -> 0.44236111 | M6: Ewallet | N6: =VALUE(IF(AND(ISERR(FIND(".",'Raw Data'!N6)),LEN('Raw Data'!N6)=5), IF(YEAR('Raw Data'!N6)=2026,CONCATENATE(DAY('Raw Data'!N6),".",IF(LEN(MONTH('Raw Data'!N6))=2,MONTH('Raw Data'!N6),CONCATENATE("0",MONTH('Raw Data'!N6)))),CONCATENATE(MONTH('Raw Data'!N6),".",RIGHT(YEAR('Raw Data'!N6),2))),'Raw Data'!N6)) -> 604.17 | O6: =P6/J6*100 -> 4.7619048 | P6: =J6-N6 -> 30.2085 | Q6: =VALUE(IF(AND(ISERR(FIND(".",'Raw Data'!Q6)),LEN('Raw Data'!Q6)=5), IF(YEAR('Raw Data'!Q6)=2026,CONCATENATE(DAY('Raw Data'!Q6),".",IF(LEN(MONTH('Raw Data'!Q6))=2,MONTH('Raw Data'!Q6),CONCATENATE(MONTH('Raw Data'!Q6)))),CONCATENATE(MONTH('Raw Data'!Q6),".",RIGHT(YEAR('Raw Data'!Q6),2))),'Raw Data'!Q6)) -> 5.3
A7: 699-14-3026 | B7: C | C7: Naypyitaw | D7: Normal | E7: Male | F7: Electronic accessories | G7: =VALUE(IF(AND(ISERR(FIND(".",'Raw Data'!G7)),LEN('Raw Data'!G7)=5), IF(YEAR('Raw Data'!G7)=2026,CONCATENATE(DAY('Raw Data'!G7),".",IF(LEN(MONTH('Raw Data'!G7))=2,MONTH('Raw Data'!G7),CONCATENATE("0",MONTH('Raw Data'!G7)))),CONCATENATE(MONTH('Raw Data'!G7),".",RIGHT(YEAR('Raw Data'!G7),2))),'Raw Data'!G7)) -> 85.39 | H7: ='Raw Data'!H7 -> 7 | I7: =J7-G7*H7 -> 29.8865 | J7: ='Raw Data'!J7 -> 627.6165 | K7: =VALUE(IFERROR(VALUE('Raw Data'!K7),CONCATENATE(MID('Raw Data'!K7,3,2),".","0",LEFT('Raw Data'!K7,1),".", RIGHT('Raw Data'!K7,4)))) -> 43549 | L7: ='Raw Data'!L7 -> 0.77083333 | M7: Ewallet | N7: =VALUE(IF(AND(ISERR(FIND(".",'Raw Data'!N7)),LEN('Raw Data'!N7)=5), IF(YEAR('Raw Data'!N7)=2026,CONCATENATE(DAY('Raw Data'!N7),".",IF(LEN(MONTH('Raw Data'!N7))=2,MONTH('Raw Data'!N7),CONCATENATE("0",MONTH('Raw Data'!N7)))),CONCATENATE(MONTH('Raw Data'!N7),".",RIGHT(YEAR('Raw Data'!N7),2))),'Raw Data'!N7)) -> 597.73 | O7: =P7/J7*100 -> 4.7619048 | P7: =J7-N7 -> 29.8865 | Q7: =VALUE(IF(AND(ISERR(FIND(".",'Raw Data'!Q7)),LEN('Raw Data'!Q7)=5), IF(YEAR('Raw Data'!Q7)=2026,CONCATENATE(DAY('Raw Data'!Q7),".",IF(LEN(MONTH('Raw Data'!Q7))=2,MONTH('Raw Data'!Q7),CONCATENATE(MONTH('Raw Data'!Q7)))),CONCATENATE(MONTH('Raw Data'!Q7),".",RIGHT(YEAR('Raw Data'!Q7),2))),'Raw Data'!Q7)) -> 4.1
A8: 355-53-5943 | B8: A | C8: Yangon | D8: Member | E8: Female | F8: Electronic accessories | G8: =VALUE(IF(AND(ISERR(FIND(".",'Raw Data'!G8)),LEN('Raw Data'!G8)=5), IF(YEAR('Raw Data'!G8)=2026,CONCATENATE(DAY('Raw Data'!G8),".",IF(LEN(MONTH('Raw Data'!G8))=2,MONTH('Raw Data'!G8),CONCATENATE("0",MONTH('Raw Data'!G8)))),CONCATENATE(MONTH('Raw Data'!G8),".",RIGHT(YEAR('Raw Data'!G8),2))),'Raw Data'!G8)) -> 68.84 | H8: ='Raw Data'!H8 -> 6 | I8: =J8-G8*H8 -> 20.652 | J8: ='Raw Data'!J8 -> 433.692 | K8: =VALUE(IFERROR(VALUE('Raw Data'!K8),CONCATENATE(MID('Raw Data'!K8,3,2),".","0",LEFT('Raw Data'!K8,1),".", RIGHT('Raw Data'!K8,4)))) -> 43521 | L8: ='Raw Data'!L8 -> 0.60833333 | M8: Ewallet | N8: =VALUE(IF(AND(ISERR(FIND(".",'Raw Data'!N8)),LEN('Raw Data'!N8)=5), IF(YEAR('Raw Data'!N8)=2026,CONCATENATE(DAY('Raw Data'!N8),".",IF(LEN(MONTH('Raw Data'!N8))=2,MONTH('Raw Data'!N8),CONCATENATE("0",MONTH('Raw Data'!N8)))),CONCATENATE(MONTH('Raw Data'!N8),".",RIGHT(YEAR('Raw Data'!N8),2))),'Raw Data'!N8)) -> 413.04 | O8: =P8/J8*100 -> 4.7619048 | P8: =J8-N8 -> 20.652 | Q8: =VALUE(IF(AND(ISERR(FIND(".",'Raw Data'!Q8)),LEN('Raw Data'!Q8)=5), IF(YEAR('Raw Data'!Q8)=2026,CONCATENATE(DAY('Raw Data'!Q8),".",IF(LEN(MONTH('Raw Data'!Q8))=2,MONTH('Raw Data'!Q8),CONCATENATE(MONTH('Raw Data'!Q8)))),CONCATENATE(MONTH('Raw Data'!Q8),".",RIGHT(YEAR('Raw Data'!Q8),2))),'Raw Data'!Q8)) -> 5.8
A9: 315-22-5665 | B9: C | C9: Naypyitaw | D9: Normal | E9: Female | F9: Home and lifestyle | G9: =VALUE(IF(AND(ISERR(FIND(".",'Raw Data'!G9)),LEN('Raw Data'!G9)=5), IF(YEAR('Raw Data'!G9)=2026,CONCATENATE(DAY('Raw Data'!G9),".",IF(LEN(MONTH('Raw Data'!G9))=2,MONTH('Raw Data'!G9),CONCATENATE("0",MONTH('Raw Data'!G9)))),CONCATENATE(MONTH('Raw Data'!G9),".",RIGHT(YEAR('Raw Data'!G9),2))),'Raw Data'!G9)) -> 73.56 | H9: ='Raw Data'!H9 -> 10 | I9: =J9-G9*H9 -> 36.78 | J9: ='Raw Data'!J9 -> 772.38 | K9: =VALUE(IFERROR(VALUE('Raw Data'!K9),CONCATENATE(MID('Raw Data'!K9,3,2),".","0",LEFT('Raw Data'!K9,1),".", RIGHT('Raw Data'!K9,4)))) -> 43520 | L9: ='Raw Data'!L9 -> 0.48472222 | M9: Ewallet | N9: =VALUE(IF(AND(ISERR(FIND(".",'Raw Data'!N9)),LEN('Raw Data'!N9)=5), IF(YEAR('Raw Data'!N9)=2026,CONCATENATE(DAY('Raw Data'!N9),".",IF(LEN(MONTH('Raw Data'!N9))=2,MONTH('Raw Data'!N9),CONCATENATE("0",MONTH('Raw Data'!N9)))),CONCATENATE(MONTH('Raw Data'!N9),".",RIGHT(YEAR('Raw Data'!N9),2))),'Raw Data'!N9)) -> 735.6 | O9: =P9/J9*100 -> 4.7619048 | P9: =J9-N9 -> 36.78 | Q9: =VALUE(IF(AND(ISERR(FIND(".",'Raw Data'!Q9)),LEN('Raw Data'!Q9)=5), IF(YEAR('Raw Data'!Q9)=2026,CONCATENATE(DAY('Raw Data'!Q9),".",IF(LEN(MONTH('Raw Data'!Q9))=2,MONTH('Raw Data'!Q9),CONCATENATE(MONTH('Raw Data'!Q9)))),CONCATENATE(MONTH('Raw Data'!Q9),".",RIGHT(YEAR('Raw Data'!Q9),2))),'Raw Data'!Q9)) -> 8
A10: 665-32-9167 | B10: A | C10: Yangon | D10: Member | E10: Female | F10: Health and beauty | G10: =VALUE(IF(AND(ISERR(FIND(".",'Raw Data'!G10)),LEN('Raw Data'!G10)=5), IF(YEAR('Raw Data'!G10)=2026,CONCATENATE(DAY('Raw Data'!G10),".",IF(LEN(MONTH('Raw Data'!G10))=2,MONTH('Raw Data'!G10),CONCATENATE("0",MONTH('Raw Data'!G10)))),CONCATENATE(MONTH('Raw Data'!G10),".",RIGHT(YEAR('Raw Data'!G10),2))),'Raw Data'!G10)) -> 36.26 | H10: ='Raw Data'!H10 -> 2 | I10: =J10-G10*H10 -> 3.626 | J10: ='Raw Data'!J10 -> 76.146 | K10: =VALUE(IFERROR(VALUE('Raw Data'!K10),CONCATENATE(MID('Raw Data'!K10,3,2),".","0",LEFT('Raw Data'!K10,1),".", RIGHT('Raw Data'!K10,4)))) -> 43739 | L10: ='Raw Data'!L10 -> 0.71875 | M10: Credit card | N10: =VALUE(IF(AND(ISERR(FIND(".",'Raw Data'!N10)),LEN('Raw Data'!N10)=5), IF(YEAR('Raw Data'!N10)=2026,CONCATENATE(DAY('Raw Data'!N10),".",IF(LEN(MONTH('Raw Data'!N10))=2,MONTH('Raw Data'!N10),CONCATENATE("0",MONTH('Raw Data'!N10)))),CONCATENATE(MONTH('Raw Data'!N10),".",RIGHT(YEAR('Raw Data'!N10),2))),'Raw Data'!N10)) -> 72.52 | O10: =P10/J10*100 -> 4.7619048 | P10: =J10-N10 -> 3.626 | Q10: =VALUE(IF(AND(ISERR(FIND(".",'Raw Data'!Q10)),LEN('Raw Data'!Q10)=5), IF(YEAR('Raw Data'!Q10)=2026,CONCATENATE(DAY('Raw Data'!Q10),".",IF(LEN(MONTH('Raw Data'!Q10))=2,MONTH('Raw Data'!Q10),CONCATENATE(MONTH('Raw Data'!Q10)))),CONCATENATE(MONTH('Raw Data'!Q10),".",RIGHT(YEAR('Raw Data'!Q10),2))),'Raw Data'!Q10)) -> 7.2
A11: 692-92-5582 | B11: B | C11: Mandalay | D11: Member | E11: Female | F11: Food and beverages | G11: =VALUE(IF(AND(ISERR(FIND(".",'Raw Data'!G11)),LEN('Raw Data'!G11)=5), IF(YEAR('Raw Data'!G11)=2026,CONCATENATE(DAY('Raw Data'!G11),".",IF(LEN(MONTH('Raw Data'!G11))=2,MONTH('Raw Data'!G11),CONCATENATE("0",MONTH('Raw Data'!G11)))),CONCATENATE(MONTH('Raw Data'!G11),".",RIGHT(YEAR('Raw Data'!G11),2))),'Raw Data'!G11)) -> 54.84 | H11: ='Raw Data'!H11 -> 3 | I11: =J11-G11*H11 -> 8.226 | J11: ='Raw Data'!J11 -> 172.746 | K11: =VALUE(IFERROR(VALUE('Raw Data'!K11),CONCATENATE(MID('Raw Data'!K11,3,2),".","0",LEFT('Raw Data'!K11,1),".", RIGHT('Raw Data'!K11,4)))) -> 43516 | L11: ='Raw Data'!L11 -> 0.56041667 | M11: Credit card | N11: =VALUE(IF(AND(ISERR(FIND(".",'Raw Data'!N11)),LEN('Raw Data'!N11)=5), IF(YEAR('Raw Data'!N11)=2026,CONCATENATE(DAY('Raw Data'!N11),".",IF(LEN(MONTH('Raw Data'!N11))=2,MONTH('Raw Data'!N11),CONCATENATE("0",MONTH('Raw Data'!N11)))),CONCATENATE(MONTH('Raw Data'!N11),".",RIGHT(YEAR('Raw Data'!N11),2))),'Raw Data'!N11)) -> 164.52 | O11: =P11/J11*100 -> 4.7619048 | P11: =J11-N11 -> 8.226 | Q11: =VALUE(IF(AND(ISERR(FIND(".",'Raw Data'!Q11)),LEN('Raw Data'!Q11)=5), IF(YEAR('Raw Data'!Q11)=2026,CONCATENATE(DAY('Raw Data'!Q11),".",IF(LEN(MONTH('Raw Data'!Q11))=2,MONTH('Raw Data'!Q11),CONCATENATE(MONTH('Raw Data'!Q11)))),CONCATENATE(MONTH('Raw Data'!Q11),".",RIGHT(YEAR('Raw Data'!Q11),2))),'Raw Data'!Q11)) -> 5.9
A12: 351-62-0822 | B12: B | C12: Mandalay | D12: Member | E12: Female | F12: Fashion accessories | G12: =VALUE(IF(AND(ISERR(FIND(".",'Raw Data'!G12)),LEN('Raw Data'!G12)=5), IF(YEAR('Raw Data'!G12)=2026,CONCATENATE(DAY('Raw Data'!G12),".",IF(LEN(MONTH('Raw Data'!G12))=2,MONTH('Raw Data'!G12),CONCATENATE("0",MONTH('Raw Data'!G12)))),CONCATENATE(MONTH('Raw Data'!G12),".",RIGHT(YEAR('Raw Data'!G12),2))),'Raw Data'!G12)) -> 14.48 | H12: ='Raw Data'!H12 -> 4 | I12: =J12-G12*H12 -> 2.896 | J12: ='Raw Data'!J12 -> 60.816 | K12: =VALUE(IFERROR(VALUE('Raw Data'!K12),CONCATENATE(MID('Raw Data'!K12,3,2),".","0",LEFT('Raw Data'!K12,1),".", RIGHT('Raw Data'!K12,4)))) -> 43618 | L12: ='Raw Data'!L12 -> 0.75486111 | M12: Ewallet | N12: =VALUE(IF(AND(ISERR(FIND(".",'Raw Data'!N12)),LEN('Raw Data'!N12)=5), IF(YEAR('Raw Data'!N12)=2026,CONCATENATE(DAY('Raw Data'!N12),".",IF(LEN(MONTH('Raw Data'!N12))=2,MONTH('Raw Data'!N12),CONCATENATE("0",MONTH('Raw Data'!N12)))),CONCATENATE(MONTH('Raw Data'!N12),".",RIGHT(YEAR('Raw Data'!N12),2))),'Raw Data'!N12)) -> 57.92 | O12: =P12/J12*100 -> 4.7619048 | P12: =J12-N12 -> 2.896 | Q12: =VALUE(IF(AND(ISERR(FIND(".",'Raw Data'!Q12)),LEN('Raw Data'!Q12)=5), IF(YEAR('Raw Data'!Q12)=2026,CONCATENATE(DAY('Raw Data'!Q12),".",IF(LEN(MONTH('Raw Data'!Q12))=2,MONTH('Raw Data'!Q12),CONCATENATE(MONTH('Raw Data'!Q12)))),CONCATENATE(MONTH('Raw Data'!Q12),".",RIGHT(YEAR('Raw Data'!Q12),2))),'Raw Data'!Q12)) -> 4.5
A13: 529-56-3974 | B13: B | C13: Mandalay | D13: Member | E13: Male | F13: Electronic accessories | G13: =VALUE(IF(AND(ISERR(FIND(".",'Raw Data'!G13)),LEN('Raw Data'!G13)=5), IF(YEAR('Raw Data'!G13)=2026,CONCATENATE(DAY('Raw Data'!G13),".",IF(LEN(MONTH('Raw Data'!G13))=2,MONTH('Raw Data'!G13),CONCATENATE("0",MONTH('Raw Data'!G13)))),CONCATENATE(MONTH('Raw Data'!G13),".",RIGHT(YEAR('Raw Data'!G13),2))),'Raw Data'!G13)) -> 25.51 | H13: ='Raw Data'!H13 -> 4 | I13: =J13-G13*H13 -> 5.102 | J13: ='Raw Data'!J13 -> 107.142 | K13: =VALUE(IFERROR(VALUE('Raw Data'!K13),CONCATENATE(MID('Raw Data'!K13,3,2),".","0",LEFT('Raw Data'!K13,1),".", RIGHT('Raw Data'!K13,4)))) -> 43711 | L13: ='Raw Data'!L13 -> 0.71041667 | M13: Cash | N13: =VALUE(IF(AND(ISERR(FIND(".",'Raw Data'!N13)),LEN('Raw Data'!N13)=5), IF(YEAR('Raw Data'!N13)=2026,CONCATENATE(DAY('Raw Data'!N13),".",IF(LEN(MONTH('Raw Data'!N13))=2,MONTH('Raw Data'!N13),CONCATENATE("0",MONTH('Raw Data'!N13)))),CONCATENATE(MONTH('Raw Data'!N13),".",RIGHT(YEAR('Raw Data'!N13),2))),'Raw Data'!N13)) -> 102.04 | O13: =P13/J13*100 -> 4.7619048 | P13: =J13-N13 -> 5.102 | Q13: =VALUE(IF(AND(ISERR(FIND(".",'Raw Data'!Q13)),LEN('Raw Data'!Q13)=5), IF(YEAR('Raw Data'!Q13)=2026,CONCATENATE(DAY('Raw Data'!Q13),".",IF(LEN(MONTH('Raw Data'!Q13))=2,MONTH('Raw Data'!Q13),CONCATENATE(MONTH('Raw Data'!Q13)))),CONCATENATE(MONTH('Raw Data'!Q13),".",RIGHT(YEAR('Raw Data'!Q13),2))),'Raw Data'!Q13)) -> 6.8
... A1001: 849-09-3807 | B1001: A | C1001: Yangon | D1001: Member | E1001: Female | F1001: Fashion accessories | G1001: =VALUE(IF(AND(ISERR(FIND(".",'Raw Data'!G1001)),LEN('Raw Data'!G1001)=5), IF(YEAR('Raw Data'!G1001)=2026,CONCATENATE(DAY('Raw Data'!G1001),".",IF(LEN(MONTH('Raw Data'!G1001))=2,MONTH('Raw Data'!G1001),CONCATENATE("0",MONTH('Raw Data'!G1001)))),CONCATENATE(MONTH('Raw Data'!G1001),".",RIGHT(YEAR('Raw Data'!G1001),2))),'Raw Data'!G1001)) -> 88.34 | H1001: ='Raw Data'!H1001 -> 7 | I1001: =J1001-G1001*H1001 -> 30.919 | J1001: ='Raw Data'!J1001 -> 649.299 | K1001: =VALUE(IFERROR(VALUE('Raw Data'!K1001),CONCATENATE(MID('Raw Data'!K1001,3,2),".","0",LEFT('Raw Data'!K1001,1),".", RIGHT('Raw Data'!K1001,4)))) -> 43514 | L1001: ='Raw Data'!L1001 -> 0.56111111 | M1001: Cash | N1001: =VALUE(IF(AND(ISERR(FIND(".",'Raw Data'!N1001)),LEN('Raw Data'!N1001)=5), IF(YEAR('Raw Data'!N1001)=2026,CONCATENATE(DAY('Raw Data'!N1001),".",IF(LEN(MONTH('Raw Data'!N1001))=2,MONTH('Raw Data'!N1001),CONCATENATE("0",MONTH('Raw Data'!N1001)))),CONCATENATE(MONTH('Raw Data'!N1001),".",RIGHT(YEAR('Raw Data'!N1001),2))),'Raw Data'!N1001)) -> 618.38 | O1001: =P1001/J1001*100 -> 4.7619048 | P1001: =J1001-N1001 -> 30.919 | Q1001: =VALUE(IF(AND(ISERR(FIND(".",'Raw Data'!Q1001)),LEN('Raw Data'!Q1001)=5), IF(YEAR('Raw Data'!Q1001)=2026,CONCATENATE(DAY('Raw Data'!Q1001),".",IF(LEN(MONTH('Raw Data'!Q1001))=2,MONTH('Raw Data'!Q1001),CONCATENATE(MONTH('Raw Data'!Q1001)))),CONCATENATE(MONTH('Raw Data'!Q1001),".",RIGHT(YEAR('Raw Data'!Q1001),2))),'Raw Data'!Q1001)) -> 6.6

Sheet Pivot Tables
A1: Анализ по гендеру: | F1: Обобщенно: | I1: Анализ по типу клиента:
A3: Общая выручка | B3: Gender | F3: Общая выручка по гендеру | I3: Общая выручка по типу клиента
A4: Product line | B4: Female | C4: Male | D4: Общий итог | F4: Gender | G4: Итог | I4: Customer type | J4: Итог
A5: Electronic accessories | B5: 27102.022 | C5: 27235.509 | D5: 54337.531 | F5: Female | G5: 184642.23 | I5: Member | J5: 501
A6: Fashion accessories | B6: 47196.706 | C6: 23868.495 | D6: 71065.201 | F6: Male | G6: 186394.15 | I6: Normal | J6: 499
A7: Food and beverages | B7: 33170.917 | C7: 22973.926 | D7: 56144.844 | F7: Общий итог | G7: 371036.38 | I7: Общий итог | J7: 1000
A8: Health and beauty | B8: 18560.986 | C8: 30632.752 | D8: 49193.739
A9: Home and lifestyle | B9: 30036.878 | C9: 23825.035 | D9: 53861.913
A10: Sports and travel | B10: 28574.721 | C10: 57858.427 | D10: 86433.148
A11: Общий итог | B11: 184642.23 | C11: 186394.15 | D11: 371036.38
A13: Анализ прибыльности компании по категории товара: | F13: Анализ каналов продаж (город и филиал):
B15: Значения | G15: Значения | K15: Значения
A16: Product line | B16: Общая выручка | C16: Общая себестоимость | D16: Общая прибыль | F16: City | G16: Кол-во товаров | H16: Общая прибыль | J16: Branch | K16: Кол-во товаров | L16: Общая прибыль
A17: Electronic accessories | B17: 54337.532 | C17: 51750.03 | D17: 2587.5015 | F17: Mandalay | G17: 1820 | H17: 5057.032 | J17: A | K17: 1859 | L17: 21817.546
A18: Fashion accessories | B18: 71065.2 | C18: 51718.82 | D18: 19346.38 | F18: Naypyitaw | G18: 1831 | H18: 36575.498 | J18: B | K18: 1820 | L18: 5057.032
A19: Food and beverages | B19: 56144.844 | C19: 53471.28 | D19: 2673.564 | F19: Yangon | G19: 1859 | H19: 21817.546 | J19: C | K19: 1831 | L19: 36575.498
A20: Health and beauty | B20: 49193.739 | C20: 46851.18 | D20: 2342.559 | F20: Общий итог | G20: 5510 | H20: 63450.076 | J20: Общий итог | K20: 5510 | L20: 63450.076
A21: Home and lifestyle | B21: 53861.913 | C21: 51297.06 | D21: 2564.853
A22: Sports and travel | B22: 86433.148 | C22: 52497.93 | D22: 33935.218
A23: Общий итог | B23: 371036.38 | C23: 307586.3 | D23: 63450.076
A25: Анализ способов оплаты: | F25: Анализ времени продаж: | J25: Анализ сезонности продаж:
A27: Количество клиентов | F27: Общая выручка | J27: Общая выручка
A28: Payment | B28: Итог | F28: Часы | G28: Time | H28: Итог | J28: Месяцы | K28: Итог
A29: Cash | B29: 344 | F29: 10 | H29: 31421.481 | J29: янв | K29: 103321.87
A30: Credit card | B30: 311 | F30: 11 | H30: 30377.329 | J30: фев | K30: 63169.743
A31: Ewallet | B31: 345 | F31: 12 | H31: 26065.882 | J31: мар | K31: 72749.25
A32: Общий итог | B32: 1000 | F32: 13 | H32: 34723.227 | J32: апр | K32: 7957.6245
F33: 14 | H33: 62138.721 | J33: май | K33: 12798.692
F34: 15 | H34: 31179.508 | J34: июн | K34: 9612.225
F35: 16 | H35: 25226.323 | J35: июл | K35: 42811.035
F36: 17 | H36: 24445.218 | J36: авг | K36: 13503.777
F37: 18 | H37: 42789.645 | J37: сен | K37: 13767.285
F38: 19 | H38: 39699.513 | J38: окт | K38: 9865.2015
F39: 20 | H39: 22969.527 | J39: ноя | K39: 9618.3675
F40: Общий итог | H40: 371036.38 | J40: дек | K40: 11861.304
J41: Общий итог | K41: 371036.38

Sheet Dashboard
A1: Анализ продаж супермаркета за 2019
A3: Анализ продаж по категориям товаров, регионам, времени и способам оплаты. Данные содержат 1000+ транзакций.
A5: Ключевые выводы:
A7: 1. Гендерный анализ
A8: Мужчины и женщины приносят практически равную выручку (разница 0,5%). Мужчины предпочитают категорию "Sports and travel" (16% продаж), женщины — "Fashion accessories" (13%).
A10: Рекомендации: Сегментировать рекламные кампании, продвигая спорт и путешествия мужчинам, аксессуары — женщинам.
A43: 2. Товарная прибыльность
A44: Наибольшую прибыль дают "Sports and travel" и "Fashion accessories". У категории "Food and beverages" высокая выручка, но самая высокая себестоимость.
A46: Рекомендации: Пересмотреть закупочные цены на "Food and beverages", чтобы увеличить прибыль. Категорию "Health and beauty" (низкая прибыль) использовать как "якорную" для привлечения потока.
A65: 3. Регионы
A66: Город Naypyitaw — самый прибыльный (как и Yangon). Mandalay проваливается по выручке (в 7 раз ниже при том же количестве товара).
A68: Рекомендации: Проверить ценообразование в Mandalay: возможно, там слишком низкие цены или идут массовые распродажи.
... A168: 3. Усилить маркетинг в декабре под январский пик.
